Workbook

Sheet 設定
A1: ■ 共通設定
A2: 為替レート (USD→JPY) | B2: =IFERROR(GOOGLEFINANCE("CURRENCY:USDJPY"),159.245) -> 159.245 | D2: Google Sheetsで自動更新 / Excelではフォールバック159.245
A3: 実効プロモ率 | B3: 0.1 | D3: 販売実績実測5.82% → 6%(保守的round up)。旧11%から修正
A4: ペイオニア手数料率 | B4: 0.025 | D4: FXマークアップ+銀行出金の合算推定 (新規追加)
A5: 目標最低利益率 | B5: 0.1 | D5: 仕入GATE判定の閾値
A7: ■ 国別eBay実効手数料率
A8: 国 | B8: 実効率 | C8: 備考(実測値)
A9: US | B9: 0.185 | C9: 実測18.53%
A10: UK | B10: 0.225 | C10: 実測22.55% (VAT関連)
A11: AU | B11: 0.15 | C11: 実測14.88%
A12: EU | B12: 0.185 | C12: US相当想定
A13: その他 | B13: 0.18 | C13: 平均想定
A15: ■ カテゴリ設定
A16: カテゴリ名 | B16: 公式FVF | C16: 実送料(JPY) | D16: 備考
A17: TCG(PSA10) | B17: 0.1325 | C17: 2000 | D17: 新カテゴリ・データ蓄積中
A18: G-SHOCK | B18: 0.1325 | C18: 2000 | D18: 年11件・黒字率73%
A19: Tシャツ(UT) | B19: 0.153 | C19: 2000 | D19: ★主力 年33件・黒字率91%
A20: Montbell(一般) | B20: 0.153 | C20: 2000 | D20: バッグ小物・非アウター
A21: Montbell(ジャケット) | B21: 0.153 | C21: 4500 | D21: 嵩張り注意・送料厚め
A22: 一番くじ | B22: 0.1325 | C22: 2500 | D22: 新・実測調整中
A23: フィギュア | B23: 0.1325 | C23: 3500
A24: ユニクロ(非UT) | B24: 0.153 | C24: 2000
A25: サンリオ文具 | B25: 0.1325 | C25: 2000
A26: ヴィンテージ玩具 | B26: 0.1325 | C26: 2500
A27: トミカ | B27: 0.1325 | C27: 2000
A28: POPMart | B28: 0.1325 | C28: 2500
A29: ガシャポン | B29: 0.1325 | C29: 2000
A30: ダイソー | B30: 0.1325 | C30: 2000 | D30: 薄利注意
A31: バッグ(アネロ) | B31: 0.153 | C31: 2500
A32: サンリオぬいぐるみ | B32: 0.1325 | C32: 2500
A34: ■ eBay公式 FVF 参考値 (2026)
A35: ※ 参考情報のみ。主計算には国別実効率(B9-B13)を使用中
A37: カテゴリグループ | B37: 公式FVF | C37: +共通費 | D37: 備考
A38: TCG/Toys/Collectibles系 | B38: 0.1325 | C38: 0.1525 | D38: TCG/G-SHOCK/一番くじ/フィギュア/トミカ/ガチャ等
A39: Clothing Shoes & Accessories | B39: 0.153 | C39: 0.173 | D39: UT/ユニクロ/Montbell(全)/バッグ(アネロ)
A41: ■ 共通プラットフォーム費 (内訳)
A42: International fee (国際料) | B42: 0.0165 | D42: 日本→海外クロスボーダー販売に常時
A43: Regulatory operating fee | B43: 0.0035 | D43: 静的な規制手数料
A44: 合計 (カテゴリFVFに加算) | B44: 0.02 | D44: 大半のクロスボーダー販売で常時加算
A45: Per order fee ≤$10 | D45: $0.30 固定
...

Sheet US計算
A1: 国 | B1: US | C1: 為替 | D1: =設定!$B$2 -> 159.245 | E1: カテゴリ | F1: Montbell(ジャケット) | H1: 手数料率 | I1: =VLOOKUP(F1,設定!$A$17:$B$32,2,FALSE)+0.02+K1 -> 0.173 | J1: 国別補正 | K1: 0 | R1: プロモ | S1: =設定!$B$3 -> 0.1 | T1: Payo | U1: =設定!$B$4 -> 0.025
A2: 送料込み | B2: 割引率 | D2: 出品価格($) | E2: 仕入(¥) | F2: ポイント還元 | G2: 売上(¥) | H2: 実送料(¥) | I2: eBay手数料(¥) | J2: DDP送料($) | K2: プロモ率 | L2: 利益(¥) | M2: 利益率 | N2: プロモ費(¥) | P2: Payo費(¥)
A3: =D3+J3 -> 180.98 | B3: 推奨 | C3: =J18 -> 130.98 | D3: =INT(C3)+0.98 -> 130.98 | E3: =$E$4 -> 6800 | F3: =$F$4 -> 2323 | G3: =D3*$D$1 -> 20857.91 | H3: =$H$4 -> 2000 | I3: =((D3+J3)*$D$1)*$I$1 -> 4985.8877 | J3: =_xlfn.IFS(D3>=800,260,D3>=600,210,D3>=500,155,D3>=400,130,D3>=300,105,D3>=200,75,D3>=100,50,D3>=60,30,D3>=40,20,D3<40,15) -> 50 | K3: =$S$1 -> 0.1 | L3: =G3-H3-I3-E3-N3-P3+F3 -> 5991.5586 | M3: =L3/G3 -> 0.28725594 | N3: =(D3+J3)*K3*$D$1 -> 2882.016 | P3: =G3*$U$1 -> 521.44775
A4: =D4+J4 -> 160.98 | B4: 出品中 | C4: 110 | D4: =INT(C4)+0.98 -> 110.98 | E4: 6800 | F4: 2323 | G4: =D4*$D$1 -> 17673.01 | H4: 2000 | I4: =((D4+J4)*$D$1)*$I$1 -> 4434.9 | J4: =_xlfn.IFS(D4>=800,260,D4>=600,210,D4>=500,155,D4>=400,130,D4>=300,105,D4>=200,75,D4>=100,50,D4>=60,30,D4>=40,20,D4<40,15) -> 50 | K4: =$S$1 -> 0.1 | L4: =G4-H4-I4-E4-N4-P4+F4 -> 3755.7588 | M4: =L4/G4 -> 0.21251382 | N4: =(D4+J4)*K4*$D$1 -> 2563.526 | P4: =G4*$U$1 -> 441.82525
A5: =D5+J5 -> 154.98 | B5: 0.05 | C5: =$C$4*(1-B5) -> 104.5 | D5: =INT(C5)+0.98 -> 104.98 | E5: =$E$4 -> 6800 | F5: =$F$4 -> 2323 | G5: =D5*$D$1 -> 16717.54 | H5: =$H$4 -> 2000 | I5: =((D5+J5)*$D$1)*$I$1 -> 4269.6037 | J5: =_xlfn.IFS(D5>=800,260,D5>=600,210,D5>=500,155,D5>=400,130,D5>=300,105,D5>=200,75,D5>=100,50,D5>=60,30,D5>=40,20,D5<40,15) -> 50 | K5: =$S$1 -> 0.1 | L5: =G5-H5-I5-E5-N5-P5+F5 -> 3085.0189 | M5: =L5/G5 -> 0.18453785 | N5: =(D5+J5)*K5*$D$1 -> 2467.979 | P5: =G5*$U$1 -> 417.9385
A6: =D6+J6 -> 151.98 | B6: 0.08 | C6: =$C$4*(1-B6) -> 101.2 | D6: =INT(C6)+0.98 -> 101.98 | E6: =$E$4 -> 6800 | F6: =$F$4 -> 2323 | G6: =D6*$D$1 -> 16239.805 | H6: =$H$4 -> 2000 | I6: =((D6+J6)*$D$1)*$I$1 -> 4186.9555 | J6: =_xlfn.IFS(D6>=800,260,D6>=600,210,D6>=500,155,D6>=400,130,D6>=300,105,D6>=200,75,D6>=100,50,D6>=60,30,D6>=40,20,D6<40,15) -> 50 | K6: =$S$1 -> 0.1 | L6: =G6-H6-I6-E6-N6-P6+F6 -> 2749.6489 | M6: =L6/G6 -> 0.16931539 | N6: =(D6+J6)*K6*$D$1 -> 2420.2055 | P6: =G6*$U$1 -> 405.99513
A7: =D7+J7 -> 129.98 | B7: 0.1 | C7: =$C$4*(1-B7) -> 99 | D7: =INT(C7)+0.98 -> 99.98 | E7: =$E$4 -> 6800 | F7: =$F$4 -> 2323 | G7: =D7*$D$1 -> 15921.315 | H7: =$H$4 -> 2000 | I7: =((D7+J7)*$D$1)*$I$1 -> 3580.8691 | J7: =_xlfn.IFS(D7>=800,260,D7>=600,210,D7>=500,155,D7>=400,130,D7>=300,105,D7>=200,75,D7>=100,50,D7>=60,30,D7>=40,20,D7<40,15) -> 30 | K7: =$S$1 -> 0.1 | L7: =G7-H7-I7-E7-N7-P7+F7 -> 3395.5467 | M7: =L7/G7 -> 0.21327049 | N7: =(D7+J7)*K7*$D$1 -> 2069.8665 | P7: =G7*$U$1 -> 398.03288
A8: =D8+J8 -> 123.98 | B8: 0.15 | C8: =$C$4*(1-B8) -> 93.5 | D8: =INT(C8)+0.98 -> 93.98 | E8: =$E$4 -> 6800 | F8: =$F$4 -> 2323 | G8: =D8*$D$1 -> 14965.845 | H8: =$H$4 -> 2000 | I8: =((D8+J8)*$D$1)*$I$1 -> 3415.5728 | J8: =_xlfn.IFS(D8>=800,260,D8>=600,210,D8>=500,155,D8>=400,130,D8>=300,105,D8>=200,75,D8>=100,50,D8>=60,30,D8>=40,20,D8<40,15) -> 30 | K8: =$S$1 -> 0.1 | L8: =G8-H8-I8-E8-N8-P8+F8 -> 2724.8067 | M8: =L8/G8 -> 0.18206835 | N8: =(D8+J8)*K8*$D$1 -> 1974.3195 | P8: =G8*$U$1 -> 374.14613
A11: =D11+J11 -> 180.98 | B11: オファー価格 | C11: =J18 -> 130.98 | D11: =INT(C11)+0.98 -> 130.98 | E11: =$E$4 -> 6800 | F11: =$F$4 -> 2323 | G11: =D11*$D$1 -> 20857.91 | H11: =$H$4 -> 2000 | I11: =((D11+J11)*$D$1)*$I$1 -> 4985.8877 | J11: =_xlfn.IFS(D11>=800,260,D11>=600,210,D11>=500,155,D11>=400,130,D11>=300,105,D11>=200,75,D11>=100,50,D11>=60,30,D11>=40,20,D11<40,15) -> 50 | K11: =$S$1 -> 0.1 | L11: =G11-H11-I11-E11-N11-P11+F11 -> 5991.5586 | M11: =L11/G11 -> 0.28725594 | N11: =(D11+J11)*K11*$D$1 -> 2882.016 | P11: =G11*$U$1 -> 521.44775
A12: =D12+J12 -> 315.98 | B12: 試算用 | C12: 240 | D12: =INT(C12)+0.98 -> 240.98 | E12: =$E$4 -> 6800 | F12: =$F$4 -> 2323 | G12: =D12*$D$1 -> 38374.86 | H12: =$H$4 -> 2000 | I12: =((D12+J12)*$D$1)*$I$1 -> 8705.0547 | J12: =_xlfn.IFS(D12>=800,260,D12>=600,210,D12>=500,155,D12>=400,130,D12>=300,105,D12>=200,75,D12>=100,50,D12>=60,30,D12>=40,20,D12<40,15) -> 75 | K12: =$S$1 -> 0.1 | L12: =G12-H12-I12-E12-N12-P12+F12 -> 17201.61 | M12: =L12/G12 -> 0.44825207 | N12: =(D12+J12)*K12*$D$1 -> 5031.8235 | P12: =G12*$U$1 -> 959.3715
C15: ■ カテゴリ別参考価格 (/140 参考レート基準)
D16: 手数料 | E16: 実送料 | H16: 仕入 | I16: SS | J16: A | K16: B | L16: C | M16: D | N16: E | O16: E2
C17: TCG(PSA10) | D17: 0.1325 | E17: 2000 | H17: =E4 -> 6800 | I17: =ROUNDDOWN(((H17+E17+5000)/(1-(D17+0.02+$K$1)-$S$1-$U$1))/140,0)+0.98 -> 136.98 | J17: =ROUNDDOWN(((H17+E17+4000)/(1-(D17+0.02+$K$1)-$S$1-$U$1))/140,0)+0.98 -> 126.98 | K17: =ROUNDDOWN(((H17+E17+3000)/(1-(D17+0.02+$K$1)-$S$1-$U$1))/140,0)+0.98 -> 116.98 | L17: =ROUNDDOWN(((H17+E17+2000)/(1-(D17+0.02+$K$1)-$S$1-$U$1))/140,0)+0.98 -> 106.98 | M17: =ROUNDDOWN(((H17+E17+1000)/(1-(D17+0.02+$K$1)-$S$1-$U$1))/140,0)+0.98 -> 96.98 | N17: =ROUNDDOWN(((H17+E17+500)/(1-(D17+0.02+$K$1)-$S$1-$U$1))/140,0)+0.98 -> 91.98 | O17: =ROUNDDOWN(((H17+E17+0)/(1-(D17+0.02+$K$1)-$S$1-$U$1))/140,0)+0.98 -> 86.98
C18: Tシャツ/Montbell一般 | D18: 0.153 | E18: 2000 | H18: =E4 -> 6800 | I18: =ROUNDDOWN(((H18+E18+5000)/(1-(D18+0.02+$K$1)-$S$1-$U$1))/140,0)+0.98 -> 140.98 | J18: =ROUNDDOWN(((H18+E18+4000)/(1-(D18+0.02+$K$1)-$S$1-$U$1))/140,0)+0.98 -> 130.98 | K18: =ROUNDDOWN(((H18+E18+3000)/(1-(D18+0.02+$K$1)-$S$1-$U$1))/140,0)+0.98 -> 120.98 | L18: =ROUNDDOWN(((H18+E18+2000)/(1-(D18+0.02+$K$1)-$S$1-$U$1))/140,0)+0.98 -> 109.98 | M18: =ROUNDDOWN(((H18+E18+1000)/(1-(D18+0.02+$K$1)-$S$1-$U$1))/140,0)+0.98 -> 99.98 | N18: =ROUNDDOWN(((H18+E18+500)/(1-(D18+0.02+$K$1)-$S$1-$U$1))/140,0)+0.98 -> 94.98 | O18: =ROUNDDOWN(((H18+E18+0)/(1-(D18+0.02+$K$1)-$S$1-$U$1))/140,0)+0.98 -> 89.98
C19: フィギュア | D19: 0.1325 | E19: 3500 | H19: =E4 -> 6800 | I19: =ROUNDDOWN(((H19+E19+5000)/(1-(D19+0.02+$K$1)-$S$1-$U$1))/140,0)+0.98 -> 151.98 | J19: =ROUNDDOWN(((H19+E19+4000)/(1-(D19+0.02+$K$1)-$S$1-$U$1))/140,0)+0.98 -> 141.98 | K19: =ROUNDDOWN(((H19+E19+3000)/(1-(D19+0.02+$K$1)-$S$1-$U$1))/140,0)+0.98 -> 131.98 | L19: =ROUNDDOWN(((H19+E19+2000)/(1-(D19+0.02+$K$1)-$S$1-$U$1))/140,0)+0.98 -> 121.98 | M19: =ROUNDDOWN(((H19+E19+1000)/(1-(D19+0.02+$K$1)-$S$1-$U$1))/140,0)+0.98 -> 111.98 | N19: =ROUNDDOWN(((H19+E19+500)/(1-(D19+0.02+$K$1)-$S$1-$U$1))/140,0)+0.98 -> 106.98 | O19: =ROUNDDOWN(((H19+E19+0)/(1-(D19+0.02+$K$1)-$S$1-$U$1))/140,0)+0.98 -> 101.98
C20: G-SHOCK | D20: 0.1325 | E20: 2000 | H20: =E4 -> 6800 | I20: =ROUNDDOWN(((H20+E20+5000)/(1-(D20+0.02+$K$1)-$S$1-$U$1))/140,0)+0.98 -> 136.98 | J20: =ROUNDDOWN(((H20+E20+4000)/(1-(D20+0.02+$K$1)-$S$1-$U$1))/140,0)+0.98 -> 126.98 | K20: =ROUNDDOWN(((H20+E20+3000)/(1-(D20+0.02+$K$1)-$S$1-$U$1))/140,0)+0.98 -> 116.98 | L20: =ROUNDDOWN(((H20+E20+2000)/(1-(D20+0.02+$K$1)-$S$1-$U$1))/140,0)+0.98 -> 106.98 | M20: =ROUNDDOWN(((H20+E20+1000)/(1-(D20+0.02+$K$1)-$S$1-$U$1))/140,0)+0.98 -> 96.98 | N20: =ROUNDDOWN(((H20+E20+500)/(1-(D20+0.02+$K$1)-$S$1-$U$1))/140,0)+0.98 -> 91.98 | O20: =ROUNDDOWN(((H20+E20+0)/(1-(D20+0.02+$K$1)-$S$1-$U$1))/140,0)+0.98 -> 86.98
C21: Montbell(ジャケット) | D21: 0.153 | E21: 4500 | H21: =E4 -> 6800 | I21: =ROUNDDOWN(((H21+E21+5000)/(1-(D21+0.02+$K$1)-$S$1-$U$1))/140,0)+0.98 -> 165.98 | J21: =ROUNDDOWN(((H21+E21+4000)/(1-(D21+0.02+$K$1)-$S$1-$U$1))/140,0)+0.98 -> 155.98 | K21: =ROUNDDOWN(((H21+E21+3000)/(1-(D21+0.02+$K$1)-$S$1-$U$1))/140,0)+0.98 -> 145.98 | L21: =ROUNDDOWN(((H21+E21+2000)/(1-(D21+0.02+$K$1)-$S$1-$U$1))/140,0)+0.98 -> 135.98 | M21: =ROUNDDOWN(((H21+E21+1000)/(1-(D21+0.02+$K$1)-$S$1-$U$1))/140,0)+0.98 -> 125.98 | N21: =ROUNDDOWN(((H21+E21+500)/(1-(D21+0.02+$K$1)-$S$1-$U$1))/140,0)+0.98 -> 120.98 | O21: =ROUNDDOWN(((H21+E21+0)/(1-(D21+0.02+$K$1)-$S$1-$U$1))/140,0)+0.98 -> 114.98
C23: ※ /140 は意図的な参考レート (C4で手動調整する運用)
C24: ※ net_ratio = 1 - 手数料 - プロモ - Payo で国別自動補正済

Sheet UK計算
A1: 国 | B1: UK | C1: 為替 | D1: =設定!$B$2 -> 159.245 | E1: カテゴリ | F1: TCG(PSA10) | H1: 手数料率 | I1: =VLOOKUP(F1,設定!$A$17:$B$32,2,FALSE)+0.02+K1 -> 0.2025 | J1: 国別補正 | K1: 0.05 | R1: プロモ | S1: =設定!$B$3 -> 0.1 | T1: Payo | U1: =設定!$B$4 -> 0.025
A2: 送料込み | B2: 割引率 | D2: 出品価格($) | E2: 仕入(¥) | F2: ポイント還元 | G2: 売上(¥) | H2: 実送料(¥) | I2: eBay手数料(¥) | J2: DDP送料($) | K2: プロモ率 | L2: 利益(¥) | M2: 利益率 | N2: プロモ費(¥) | P2: Payo費(¥)
A3: =D3+J3 -> 601.98 | B3: 推奨 | C3: =J18 -> 471.98 | D3: =INT(C3)+0.98 -> 471.98 | E3: =$E$4 -> 37000 | F3: =$F$4 -> 0 | G3: =D3*$D$1 -> 75160.455 | H3: =$H$4 -> 2000 | I3: =((D3+J3)*$D$1)*$I$1 -> 19412.117 | J3: =_xlfn.IFS(D3>=800,260,D3>=600,210,D3>=500,155,D3>=400,130,D3>=300,105,D3>=200,75,D3>=100,50,D3>=60,30,D3>=40,20,D3<40,15) -> 130 | K3: =$S$1 -> 0.1 | L3: =G3-H3-I3-E3-N3-P3+F3 -> 5283.0964 | M3: =L3/G3 -> 0.070290905 | N3: =(D3+J3)*K3*$D$1 -> 9586.2305 | P3: =G3*$U$1 -> 1879.0114
A4: =D4+J4 -> 562.98 | B4: 出品中 | C4: 432 | D4: =INT(C4)+0.98 -> 432.98 | E4: 37000 | F4: 0 | G4: =D4*$D$1 -> 68949.9 | H4: 2000 | I4: =((D4+J4)*$D$1)*$I$1 -> 18154.479 | J4: =_xlfn.IFS(D4>=800,260,D4>=600,210,D4>=500,155,D4>=400,130,D4>=300,105,D4>=200,75,D4>=100,50,D4>=60,30,D4>=40,20,D4<40,15) -> 130 | K4: =$S$1 -> 0.1 | L4: =G4-H4-I4-E4-N4-P4+F4 -> 1106.4982 | M4: =L4/G4 -> 0.016047858 | N4: =(D4+J4)*K4*$D$1 -> 8965.175 | P4: =G4*$U$1 -> 1723.7475
A5: =D5+J5 -> 540.98 | B5: 0.05 | C5: =$C$4*(1-B5) -> 410.4 | D5: =INT(C5)+0.98 -> 410.98 | E5: =$E$4 -> 37000 | F5: =$F$4 -> 0 | G5: =D5*$D$1 -> 65446.51 | H5: =$H$4 -> 2000 | I5: =((D5+J5)*$D$1)*$I$1 -> 17445.043 | J5: =_xlfn.IFS(D5>=800,260,D5>=600,210,D5>=500,155,D5>=400,130,D5>=300,105,D5>=200,75,D5>=100,50,D5>=60,30,D5>=40,20,D5<40,15) -> 130 | K5: =$S$1 -> 0.1 | L5: =G5-H5-I5-E5-N5-P5+F5 -> -1249.5316 | M5: =L5/G5 -> -0.01909241 | N5: =(D5+J5)*K5*$D$1 -> 8614.836 | P5: =G5*$U$1 -> 1636.1628
A6: =D6+J6 -> 502.98 | B6: 0.08 | C6: =$C$4*(1-B6) -> 397.44 | D6: =INT(C6)+0.98 -> 397.98 | E6: =$E$4 -> 37000 | F6: =$F$4 -> 0 | G6: =D6*$D$1 -> 63376.325 | H6: =$H$4 -> 2000 | I6: =((D6+J6)*$D$1)*$I$1 -> 16219.653 | J6: =_xlfn.IFS(D6>=800,260,D6>=600,210,D6>=500,155,D6>=400,130,D6>=300,105,D6>=200,75,D6>=100,50,D6>=60,30,D6>=40,20,D6<40,15) -> 105 | K6: =$S$1 -> 0.1 | L6: =G6-H6-I6-E6-N6-P6+F6 -> -1437.4407 | M6: =L6/G6 -> -0.022681036 | N6: =(D6+J6)*K6*$D$1 -> 8009.705 | P6: =G6*$U$1 -> 1584.4081
A7: =D7+J7 -> 493.98 | B7: 0.1 | C7: =$C$4*(1-B7) -> 388.8 | D7: =INT(C7)+0.98 -> 388.98 | E7: =$E$4 -> 37000 | F7: =$F$4 -> 0 | G7: =D7*$D$1 -> 61943.12 | H7: =$H$4 -> 2000 | I7: =((D7+J7)*$D$1)*$I$1 -> 15929.429 | J7: =_xlfn.IFS(D7>=800,260,D7>=600,210,D7>=500,155,D7>=400,130,D7>=300,105,D7>=200,75,D7>=100,50,D7>=60,30,D7>=40,20,D7<40,15) -> 105 | K7: =$S$1 -> 0.1 | L7: =G7-H7-I7-E7-N7-P7+F7 -> -2401.271 | M7: =L7/G7 -> -0.038765743 | N7: =(D7+J7)*K7*$D$1 -> 7866.3845 | P7: =G7*$U$1 -> 1548.578
A8: =D8+J8 -> 472.98 | B8: 0.15 | C8: =$C$4*(1-B8) -> 367.2 | D8: =INT(C8)+0.98 -> 367.98 | E8: =$E$4 -> 37000 | F8: =$F$4 -> 0 | G8: =D8*$D$1 -> 58598.975 | H8: =$H$4 -> 2000 | I8: =((D8+J8)*$D$1)*$I$1 -> 15252.239 | J8: =_xlfn.IFS(D8>=800,260,D8>=600,210,D8>=500,155,D8>=400,130,D8>=300,105,D8>=200,75,D8>=100,50,D8>=60,30,D8>=40,20,D8<40,15) -> 105 | K8: =$S$1 -> 0.1 | L8: =G8-H8-I8-E8-N8-P8+F8 -> -4650.2086 | M8: =L8/G8 -> -0.079356483 | N8: =(D8+J8)*K8*$D$1 -> 7531.97 | P8: =G8*$U$1 -> 1464.9744
A11: =D11+J11 -> 601.98 | B11: オファー価格 | C11: =J18 -> 471.98 | D11: =INT(C11)+0.98 -> 471.98 | E11: =$E$4 -> 37000 | F11: =$F$4 -> 0 | G11: =D11*$D$1 -> 75160.455 | H11: =$H$4 -> 2000 | I11: =((D11+J11)*$D$1)*$I$1 -> 19412.117 | J11: =_xlfn.IFS(D11>=800,260,D11>=600,210,D11>=500,155,D11>=400,130,D11>=300,105,D11>=200,75,D11>=100,50,D11>=60,30,D11>=40,20,D11<40,15) -> 130 | K11: =$S$1 -> 0.1 | L11: =G11-H11-I11-E11-N11-P11+F11 -> 5283.0964 | M11: =L11/G11 -> 0.070290905 | N11: =(D11+J11)*K11*$D$1 -> 9586.2305 | P11: =G11*$U$1 -> 1879.0114
A12: =D12+J12 -> 315.98 | B12: 試算用 | C12: 240 | D12: =INT(C12)+0.98 -> 240.98 | E12: =$E$4 -> 37000 | F12: =$F$4 -> 0 | G12: =D12*$D$1 -> 38374.86 | H12: =$H$4 -> 2000 | I12: =((D12+J12)*$D$1)*$I$1 -> 10189.443 | J12: =_xlfn.IFS(D12>=800,260,D12>=600,210,D12>=500,155,D12>=400,130,D12>=300,105,D12>=200,75,D12>=100,50,D12>=60,30,D12>=40,20,D12<40,15) -> 75 | K12: =$S$1 -> 0.1 | L12: =G12-H12-I12-E12-N12-P12+F12 -> -16805.778 | M12: =L12/G12 -> -0.43793717 | N12: =(D12+J12)*K12*$D$1 -> 5031.8235 | P12: =G12*$U$1 -> 959.3715
C15: ■ カテゴリ別参考価格 (/140 参考レート基準)
D16: 手数料 | E16: 実送料 | H16: 仕入 | I16: SS | J16: A | K16: B | L16: C | M16: D | N16: E | O16: E2
C17: TCG(PSA10) | D17: 0.1325 | E17: 2000 | H17: =E4 -> 37000 | I17: =ROUNDDOWN(((H17+E17+5000)/(1-(D17+0.02+$K$1)-$S$1-$U$1))/140,0)+0.98 -> 467.98 | J17: =ROUNDDOWN(((H17+E17+4000)/(1-(D17+0.02+$K$1)-$S$1-$U$1))/140,0)+0.98 -> 456.98 | K17: =ROUNDDOWN(((H17+E17+3000)/(1-(D17+0.02+$K$1)-$S$1-$U$1))/140,0)+0.98 -> 446.98 | L17: =ROUNDDOWN(((H17+E17+2000)/(1-(D17+0.02+$K$1)-$S$1-$U$1))/140,0)+0.98 -> 435.98 | M17: =ROUNDDOWN(((H17+E17+1000)/(1-(D17+0.02+$K$1)-$S$1-$U$1))/140,0)+0.98 -> 424.98 | N17: =ROUNDDOWN(((H17+E17+500)/(1-(D17+0.02+$K$1)-$S$1-$U$1))/140,0)+0.98 -> 419.98 | O17: =ROUNDDOWN(((H17+E17+0)/(1-(D17+0.02+$K$1)-$S$1-$U$1))/140,0)+0.98 -> 414.98
C18: Tシャツ/Montbell一般 | D18: 0.153 | E18: 2000 | H18: =E4 -> 37000 | I18: =ROUNDDOWN(((H18+E18+5000)/(1-(D18+0.02+$K$1)-$S$1-$U$1))/140,0)+0.98 -> 482.98 | J18: =ROUNDDOWN(((H18+E18+4000)/(1-(D18+0.02+$K$1)-$S$1-$U$1))/140,0)+0.98 -> 471.98 | K18: =ROUNDDOWN(((H18+E18+3000)/(1-(D18+0.02+$K$1)-$S$1-$U$1))/140,0)+0.98 -> 460.98 | L18: =ROUNDDOWN(((H18+E18+2000)/(1-(D18+0.02+$K$1)-$S$1-$U$1))/140,0)+0.98 -> 449.98 | M18: =ROUNDDOWN(((H18+E18+1000)/(1-(D18+0.02+$K$1)-$S$1-$U$1))/140,0)+0.98 -> 438.98 | N18: =ROUNDDOWN(((H18+E18+500)/(1-(D18+0.02+$K$1)-$S$1-$U$1))/140,0)+0.98 -> 432.98 | O18: =ROUNDDOWN(((H18+E18+0)/(1-(D18+0.02+$K$1)-$S$1-$U$1))/140,0)+0.98 -> 427.98
C19: フィギュア | D19: 0.1325 | E19: 3500 | H19: =E4 -> 37000 | I19: =ROUNDDOWN(((H19+E19+5000)/(1-(D19+0.02+$K$1)-$S$1-$U$1))/140,0)+0.98 -> 483.98 | J19: =ROUNDDOWN(((H19+E19+4000)/(1-(D19+0.02+$K$1)-$S$1-$U$1))/140,0)+0.98 -> 472.98 | K19: =ROUNDDOWN(((H19+E19+3000)/(1-(D19+0.02+$K$1)-$S$1-$U$1))/140,0)+0.98 -> 462.98 | L19: =ROUNDDOWN(((H19+E19+2000)/(1-(D19+0.02+$K$1)-$S$1-$U$1))/140,0)+0.98 -> 451.98 | M19: =ROUNDDOWN(((H19+E19+1000)/(1-(D19+0.02+$K$1)-$S$1-$U$1))/140,0)+0.98 -> 440.98 | N19: =ROUNDDOWN(((H19+E19+500)/(1-(D19+0.02+$K$1)-$S$1-$U$1))/140,0)+0.98 -> 435.98 | O19: =ROUNDDOWN(((H19+E19+0)/(1-(D19+0.02+$K$1)-$S$1-$U$1))/140,0)+0.98 -> 430.98
C20: G-SHOCK | D20: 0.1325 | E20: 2000 | H20: =E4 -> 37000 | I20: =ROUNDDOWN(((H20+E20+5000)/(1-(D20+0.02+$K$1)-$S$1-$U$1))/140,0)+0.98 -> 467.98 | J20: =ROUNDDOWN(((H20+E20+4000)/(1-(D20+0.02+$K$1)-$S$1-$U$1))/140,0)+0.98 -> 456.98 | K20: =ROUNDDOWN(((H20+E20+3000)/(1-(D20+0.02+$K$1)-$S$1-$U$1))/140,0)+0.98 -> 446.98 | L20: =ROUNDDOWN(((H20+E20+2000)/(1-(D20+0.02+$K$1)-$S$1-$U$1))/140,0)+0.98 -> 435.98 | M20: =ROUNDDOWN(((H20+E20+1000)/(1-(D20+0.02+$K$1)-$S$1-$U$1))/140,0)+0.98 -> 424.98 | N20: =ROUNDDOWN(((H20+E20+500)/(1-(D20+0.02+$K$1)-$S$1-$U$1))/140,0)+0.98 -> 419.98 | O20: =ROUNDDOWN(((H20+E20+0)/(1-(D20+0.02+$K$1)-$S$1-$U$1))/140,0)+0.98 -> 414.98
C21: Montbell(ジャケット) | D21: 0.153 | E21: 4500 | H21: =E4 -> 37000 | I21: =ROUNDDOWN(((H21+E21+5000)/(1-(D21+0.02+$K$1)-$S$1-$U$1))/140,0)+0.98 -> 509.98 | J21: =ROUNDDOWN(((H21+E21+4000)/(1-(D21+0.02+$K$1)-$S$1-$U$1))/140,0)+0.98 -> 498.98 | K21: =ROUNDDOWN(((H21+E21+3000)/(1-(D21+0.02+$K$1)-$S$1-$U$1))/140,0)+0.98 -> 487.98 | L21: =ROUNDDOWN(((H21+E21+2000)/(1-(D21+0.02+$K$1)-$S$1-$U$1))/140,0)+0.98 -> 476.98 | M21: =ROUNDDOWN(((H21+E21+1000)/(1-(D21+0.02+$K$1)-$S$1-$U$1))/140,0)+0.98 -> 465.98 | N21: =ROUNDDOWN(((H21+E21+500)/(1-(D21+0.02+$K$1)-$S$1-$U$1))/140,0)+0.98 -> 460.98 | O21: =ROUNDDOWN(((H21+E21+0)/(1-(D21+0.02+$K$1)-$S$1-$U$1))/140,0)+0.98 -> 454.98
C23: ※ /140 は意図的な参考レート (C4で手動調整する運用)
C24: ※ net_ratio = 1 - 手数料 - プロモ - Payo で国別自動補正済

Sheet AU計算
A1: 国 | B1: AU | C1: 為替 | D1: =設定!$B$2 -> 159.245 | E1: カテゴリ | F1: TCG(PSA10) | H1: 手数料率 | I1: =VLOOKUP(F1,設定!$A$17:$B$32,2,FALSE)+0.02+K1 -> 0.1325 | J1: 国別補正 | K1: -0.02 | R1: プロモ | S1: =設定!$B$3 -> 0.1 | T1: Payo | U1: =設定!$B$4 -> 0.025
A2: 送料込み | B2: 割引率 | D2: 出品価格($) | E2: 仕入(¥) | F2: ポイント還元 | G2: 売上(¥) | H2: 実送料(¥) | I2: eBay手数料(¥) | J2: DDP送料($) | K2: プロモ率 | L2: 利益(¥) | M2: 利益率 | N2: プロモ費(¥) | P2: Payo費(¥)
A3: =D3+J3 -> 206.98 | B3: 推奨 | C3: =J18 -> 156.98 | D3: =INT(C3)+0.98 -> 156.98 | E3: =$E$4 -> 9800 | F3: =$F$4 -> 0 | G3: =D3*$D$1 -> 24998.28 | H3: =$H$4 -> 2000 | I3: =((D3+J3)*$D$1)*$I$1 -> 4367.2702 | J3: =_xlfn.IFS(D3>=800,260,D3>=600,210,D3>=500,155,D3>=400,130,D3>=300,105,D3>=200,75,D3>=100,50,D3>=60,30,D3>=40,20,D3<40,15) -> 50 | K3: =$S$1 -> 0.1 | L3: =G3-H3-I3-E3-N3-P3+F3 -> 4909.9998 | M3: =L3/G3 -> 0.19641351 | N3: =(D3+J3)*K3*$D$1 -> 3296.053 | P3: =G3*$U$1 -> 624.957
A4: =D4+J4 -> 562.98 | B4: 出品中 | C4: 432 | D4: =INT(C4)+0.98 -> 432.98 | E4: 9800 | F4: 0 | G4: =D4*$D$1 -> 68949.9 | H4: 2000 | I4: =((D4+J4)*$D$1)*$I$1 -> 11878.857 | J4: =_xlfn.IFS(D4>=800,260,D4>=600,210,D4>=500,155,D4>=400,130,D4>=300,105,D4>=200,75,D4>=100,50,D4>=60,30,D4>=40,20,D4<40,15) -> 130 | K4: =$S$1 -> 0.1 | L4: =G4-H4-I4-E4-N4-P4+F4 -> 34582.121 | M4: =L4/G4 -> 0.50155433 | N4: =(D4+J4)*K4*$D$1 -> 8965.175 | P4: =G4*$U$1 -> 1723.7475
A5: =D5+J5 -> 540.98 | B5: 0.05 | C5: =$C$4*(1-B5) -> 410.4 | D5: =INT(C5)+0.98 -> 410.98 | E5: =$E$4 -> 9800 | F5: =$F$4 -> 0 | G5: =D5*$D$1 -> 65446.51 | H5: =$H$4 -> 2000 | I5: =((D5+J5)*$D$1)*$I$1 -> 11414.658 | J5: =_xlfn.IFS(D5>=800,260,D5>=600,210,D5>=500,155,D5>=400,130,D5>=300,105,D5>=200,75,D5>=100,50,D5>=60,30,D5>=40,20,D5<40,15) -> 130 | K5: =$S$1 -> 0.1 | L5: =G5-H5-I5-E5-N5-P5+F5 -> 31980.854 | M5: =L5/G5 -> 0.48865636 | N5: =(D5+J5)*K5*$D$1 -> 8614.836 | P5: =G5*$U$1 -> 1636.1628
A6: =D6+J6 -> 502.98 | B6: 0.08 | C6: =$C$4*(1-B6) -> 397.44 | D6: =INT(C6)+0.98 -> 397.98 | E6: =$E$4 -> 9800 | F6: =$F$4 -> 0 | G6: =D6*$D$1 -> 63376.325 | H6: =$H$4 -> 2000 | I6: =((D6+J6)*$D$1)*$I$1 -> 10612.859 | J6: =_xlfn.IFS(D6>=800,260,D6>=600,210,D6>=500,155,D6>=400,130,D6>=300,105,D6>=200,75,D6>=100,50,D6>=60,30,D6>=40,20,D6<40,15) -> 105 | K6: =$S$1 -> 0.1 | L6: =G6-H6-I6-E6-N6-P6+F6 -> 31369.353 | M6: =L6/G6 -> 0.49496958 | N6: =(D6+J6)*K6*$D$1 -> 8009.705 | P6: =G6*$U$1 -> 1584.4081
A7: =D7+J7 -> 493.98 | B7: 0.1 | C7: =$C$4*(1-B7) -> 388.8 | D7: =INT(C7)+0.98 -> 388.98 | E7: =$E$4 -> 9800 | F7: =$F$4 -> 0 | G7: =D7*$D$1 -> 61943.12 | H7: =$H$4 -> 2000 | I7: =((D7+J7)*$D$1)*$I$1 -> 10422.959 | J7: =_xlfn.IFS(D7>=800,260,D7>=600,210,D7>=500,155,D7>=400,130,D7>=300,105,D7>=200,75,D7>=100,50,D7>=60,30,D7>=40,20,D7<40,15) -> 105 | K7: =$S$1 -> 0.1 | L7: =G7-H7-I7-E7-N7-P7+F7 -> 30305.198 | M7: =L7/G7 -> 0.48924236 | N7: =(D7+J7)*K7*$D$1 -> 7866.3845 | P7: =G7*$U$1 -> 1548.578
A8: =D8+J8 -> 472.98 | B8: 0.15 | C8: =$C$4*(1-B8) -> 367.2 | D8: =INT(C8)+0.98 -> 367.98 | E8: =$E$4 -> 9800 | F8: =$F$4 -> 0 | G8: =D8*$D$1 -> 58598.975 | H8: =$H$4 -> 2000 | I8: =((D8+J8)*$D$1)*$I$1 -> 9979.8603 | J8: =_xlfn.IFS(D8>=800,260,D8>=600,210,D8>=500,155,D8>=400,130,D8>=300,105,D8>=200,75,D8>=100,50,D8>=60,30,D8>=40,20,D8<40,15) -> 105 | K8: =$S$1 -> 0.1 | L8: =G8-H8-I8-E8-N8-P8+F8 -> 27822.17 | M8: =L8/G8 -> 0.47478937 | N8: =(D8+J8)*K8*$D$1 -> 7531.97 | P8: =G8*$U$1 -> 1464.9744
A11: =D11+J11 -> 206.98 | B11: オファー価格 | C11: =J18 -> 156.98 | D11: =INT(C11)+0.98 -> 156.98 | E11: =$E$4 -> 9800 | F11: =$F$4 -> 0 | G11: =D11*$D$1 -> 24998.28 | H11: =$H$4 -> 2000 | I11: =((D11+J11)*$D$1)*$I$1 -> 4367.2702 | J11: =_xlfn.IFS(D11>=800,260,D11>=600,210,D11>=500,155,D11>=400,130,D11>=300,105,D11>=200,75,D11>=100,50,D11>=60,30,D11>=40,20,D11<40,15) -> 50 | K11: =$S$1 -> 0.1 | L11: =G11-H11-I11-E11-N11-P11+F11 -> 4909.9998 | M11: =L11/G11 -> 0.19641351 | N11: =(D11+J11)*K11*$D$1 -> 3296.053 | P11: =G11*$U$1 -> 624.957
A12: =D12+J12 -> 315.98 | B12: 試算用 | C12: 240 | D12: =INT(C12)+0.98 -> 240.98 | E12: =$E$4 -> 9800 | F12: =$F$4 -> 0 | G12: =D12*$D$1 -> 38374.86 | H12: =$H$4 -> 2000 | I12: =((D12+J12)*$D$1)*$I$1 -> 6667.1662 | J12: =_xlfn.IFS(D12>=800,260,D12>=600,210,D12>=500,155,D12>=400,130,D12>=300,105,D12>=200,75,D12>=100,50,D12>=60,30,D12>=40,20,D12<40,15) -> 75 | K12: =$S$1 -> 0.1 | L12: =G12-H12-I12-E12-N12-P12+F12 -> 13916.499 | M12: =L12/G12 -> 0.36264625 | N12: =(D12+J12)*K12*$D$1 -> 5031.8235 | P12: =G12*$U$1 -> 959.3715
C15: ■ カテゴリ別参考価格 (/140 参考レート基準)
D16: 手数料 | E16: 実送料 | H16: 仕入 | I16: SS | J16: A | K16: B | L16: C | M16: D | N16: E | O16: E2
C17: TCG(PSA10) | D17: 0.1325 | E17: 2000 | H17: =E4 -> 9800 | I17: =ROUNDDOWN(((H17+E17+5000)/(1-(D17+0.02+$K$1)-$S$1-$U$1))/140,0)+0.98 -> 161.98 | J17: =ROUNDDOWN(((H17+E17+4000)/(1-(D17+0.02+$K$1)-$S$1-$U$1))/140,0)+0.98 -> 151.98 | K17: =ROUNDDOWN(((H17+E17+3000)/(1-(D17+0.02+$K$1)-$S$1-$U$1))/140,0)+0.98 -> 142.98 | L17: =ROUNDDOWN(((H17+E17+2000)/(1-(D17+0.02+$K$1)-$S$1-$U$1))/140,0)+0.98 -> 132.98 | M17: =ROUNDDOWN(((H17+E17+1000)/(1-(D17+0.02+$K$1)-$S$1-$U$1))/140,0)+0.98 -> 123.98 | N17: =ROUNDDOWN(((H17+E17+500)/(1-(D17+0.02+$K$1)-$S$1-$U$1))/140,0)+0.98 -> 118.98 | O17: =ROUNDDOWN(((H17+E17+0)/(1-(D17+0.02+$K$1)-$S$1-$U$1))/140,0)+0.98 -> 113.98
C18: Tシャツ/Montbell一般 | D18: 0.153 | E18: 2000 | H18: =E4 -> 9800 | I18: =ROUNDDOWN(((H18+E18+5000)/(1-(D18+0.02+$K$1)-$S$1-$U$1))/140,0)+0.98 -> 166.98 | J18: =ROUNDDOWN(((H18+E18+4000)/(1-(D18+0.02+$K$1)-$S$1-$U$1))/140,0)+0.98 -> 156.98 | K18: =ROUNDDOWN(((H18+E18+3000)/(1-(D18+0.02+$K$1)-$S$1-$U$1))/140,0)+0.98 -> 146.98 | L18: =ROUNDDOWN(((H18+E18+2000)/(1-(D18+0.02+$K$1)-$S$1-$U$1))/140,0)+0.98 -> 136.98 | M18: =ROUNDDOWN(((H18+E18+1000)/(1-(D18+0.02+$K$1)-$S$1-$U$1))/140,0)+0.98 -> 126.98 | N18: =ROUNDDOWN(((H18+E18+500)/(1-(D18+0.02+$K$1)-$S$1-$U$1))/140,0)+0.98 -> 121.98 | O18: =ROUNDDOWN(((H18+E18+0)/(1-(D18+0.02+$K$1)-$S$1-$U$1))/140,0)+0.98 -> 116.98
C19: フィギュア | D19: 0.1325 | E19: 3500 | H19: =E4 -> 9800 | I19: =ROUNDDOWN(((H19+E19+5000)/(1-(D19+0.02+$K$1)-$S$1-$U$1))/140,0)+0.98 -> 176.98 | J19: =ROUNDDOWN(((H19+E19+4000)/(1-(D19+0.02+$K$1)-$S$1-$U$1))/140,0)+0.98 -> 166.98 | K19: =ROUNDDOWN(((H19+E19+3000)/(1-(D19+0.02+$K$1)-$S$1-$U$1))/140,0)+0.98 -> 156.98 | L19: =ROUNDDOWN(((H19+E19+2000)/(1-(D19+0.02+$K$1)-$S$1-$U$1))/140,0)+0.98 -> 147.98 | M19: =ROUNDDOWN(((H19+E19+1000)/(1-(D19+0.02+$K$1)-$S$1-$U$1))/140,0)+0.98 -> 137.98 | N19: =ROUNDDOWN(((H19+E19+500)/(1-(D19+0.02+$K$1)-$S$1-$U$1))/140,0)+0.98 -> 132.98 | O19: =ROUNDDOWN(((H19+E19+0)/(1-(D19+0.02+$K$1)-$S$1-$U$1))/140,0)+0.98 -> 127.98
C20: G-SHOCK | D20: 0.1325 | E20: 2000 | H20: =E4 -> 9800 | I20: =ROUNDDOWN(((H20+E20+5000)/(1-(D20+0.02+$K$1)-$S$1-$U$1))/140,0)+0.98 -> 161.98 | J20: =ROUNDDOWN(((H20+E20+4000)/(1-(D20+0.02+$K$1)-$S$1-$U$1))/140,0)+0.98 -> 151.98 | K20: =ROUNDDOWN(((H20+E20+3000)/(1-(D20+0.02+$K$1)-$S$1-$U$1))/140,0)+0.98 -> 142.98 | L20: =ROUNDDOWN(((H20+E20+2000)/(1-(D20+0.02+$K$1)-$S$1-$U$1))/140,0)+0.98 -> 132.98 | M20: =ROUNDDOWN(((H20+E20+1000)/(1-(D20+0.02+$K$1)-$S$1-$U$1))/140,0)+0.98 -> 123.98 | N20: =ROUNDDOWN(((H20+E20+500)/(1-(D20+0.02+$K$1)-$S$1-$U$1))/140,0)+0.98 -> 118.98 | O20: =ROUNDDOWN(((H20+E20+0)/(1-(D20+0.02+$K$1)-$S$1-$U$1))/140,0)+0.98 -> 113.98
C21: Montbell(ジャケット) | D21: 0.153 | E21: 4500 | H21: =E4 -> 9800 | I21: =ROUNDDOWN(((H21+E21+5000)/(1-(D21+0.02+$K$1)-$S$1-$U$1))/140,0)+0.98 -> 190.98 | J21: =ROUNDDOWN(((H21+E21+4000)/(1-(D21+0.02+$K$1)-$S$1-$U$1))/140,0)+0.98 -> 181.98 | K21: =ROUNDDOWN(((H21+E21+3000)/(1-(D21+0.02+$K$1)-$S$1-$U$1))/140,0)+0.98 -> 171.98 | L21: =ROUNDDOWN(((H21+E21+2000)/(1-(D21+0.02+$K$1)-$S$1-$U$1))/140,0)+0.98 -> 161.98 | M21: =ROUNDDOWN(((H21+E21+1000)/(1-(D21+0.02+$K$1)-$S$1-$U$1))/140,0)+0.98 -> 151.98 | N21: =ROUNDDOWN(((H21+E21+500)/(1-(D21+0.02+$K$1)-$S$1-$U$1))/140,0)+0.98 -> 146.98 | O21: =ROUNDDOWN(((H21+E21+0)/(1-(D21+0.02+$K$1)-$S$1-$U$1))/140,0)+0.98 -> 141.98
C23: ※ /140 は意図的な参考レート (C4で手動調整する運用)
C24: ※ net_ratio = 1 - 手数料 - プロモ - Payo で国別自動補正済

Sheet 仕入GATE
A1: ■ 仕入GATE 判定
A3: 【入力】
A4: 仕入値(JPY) | B4: 5000
A5: カテゴリ名 | B5: Tシャツ(UT) | C5: 設定シートのカテゴリ名を正確に入力 (大文字小文字/括弧まで一致)
A6: 対象国 | B6: US | C6: US / UK / AU / EU / その他
A7: eBay SOLD中央値($) | B7: 0 | C7: 直近30日・類似品のSOLD中央値を手動入力
A9: 【参照値(自動)】
A10: 参照送料(¥) | B10: =VLOOKUP(B5,設定!$A$17:$D$32,3,FALSE) -> 2000
A11: 国別手数料率 | B11: =VLOOKUP(B6,設定!$A$9:$B$13,2,FALSE) -> 0.185
A12: プロモ率 | B12: =設定!$B$3 -> 0.1
A13: ペイオニア率 | B13: =設定!$B$4 -> 0.025
A14: 目標利益率 | B14: =設定!$B$5 -> 0.1
A15: 為替レート | B15: =設定!$B$2 -> 159.245
A17: 【計算】
A18: 損益分岐 最低$ | B18: =(B4+B10)/((1-B11-B12-B13)*B15) -> 63.706412 | C18: この価格で売れば利益ゼロ
A19: 目標確保 下限$ | B19: =(B4+B10)/((1-B11-B12-B13-B14)*B15) -> 74.504109 | C19: 目標利益率を満たす最低eBay価格
A21: 【GATE判定】
A22: 判定 | B22: =IF(B7=0,"SOLD中央値未入力",IF(B7*0.9>=B19,"✅ GO","❌ NOGO")) -> SOLD中央値未入力 | C22: 条件: SOLD中央値×90% ≥ 目標確保下限$
A23: 期待売価($) | B23: =IF(B7=0,0,B7*0.95) -> 0 | C23: SOLD中央値×95% (市場より少し安く設定)
A24: 期待利益(¥) | B24: =IF(B7=0,0,B23*B15*(1-B11-B12-B13)-B4-B10) -> 0
A25: 期待利益率 | B25: =IF(OR(B7=0,B23=0),0,(B23*B15*(1-B11-B12-B13)-B4-B10)/(B23*B15)) -> 0
A28: ■ 使い方
A29: 1. メルカリで候補を見つけたら 仕入値(B4) を入力
A30: 2. カテゴリ(B5)・対象国(B6)を選択 → 送料・手数料が自動入力
A31: 3. 目標確保下限$(B19) が出る = この価格以上で売らないと目標利益が出ない
A32: 4. eBay で同等商品のSOLD中央値を調べて B7 に入力
A33: 5. GATE判定(B22) を確認:
A34: ✅ GO → 出品する価値あり (市場価格が目標下限を満たす)
A35: ❌ NOGO → 市場価格がコストプラス目標に届かない。見送り推奨
A37: ※ 判定条件は 中央値×90% ≥ 目標下限$。90%の理由: 出品価格を市場より
A38: 少し安く設定して成約率を上げるため。攻めたいなら 0.95 等に調整可
A39: ※ DDP送料・割引分は未考慮のシンプル版
A40: ※ Phase2 で iMakeBayAPI 経由で SOLD中央値を自動取得予定

Sheet 変更履歴
A1: ■ 変更履歴 (旧【NEW】利益計算シート.xlsx からの差分)
A3: 区分 | B3: 内容 | C3: 理由・備考
A4: 修正 | B4: プロモ率 0.11 → 0.06 | C4: 販売実績実測 5.82%(保守的にround up)
A5: 修正 | B5: 国別手数料率を分離 (US18.5 / UK22.5 / AU15.0) | C5: 実測: US18.53% / UK22.55% / AU14.88%
A6: 新規 | B6: ペイオニア手数料 2.5% を独立費目に | C6: FX+出金の実コストを顕在化 (隠れ費用の可視化)
A7: 新規 | B7: 設定シート (中央制御盤) | C7: 全パラメータを1箇所集約、全シートから参照
A8: 新規 | B8: 仕入GATEシート | C8: メルカリ仕入時のGO/NOGO判定 (シンプル版)
A9: 新規 | B9: Montbell(ジャケット) を別カテゴリ化 | C9: 送料4500円で分離 (過去赤字3件が全てジャケット)
A10: 改善 | B10: カテゴリ参考価格の後費用率を国別自動補正 | C10: 旧: /0.72 固定 → 新: 1 - 手数料 - プロモ - Payo
A11: 保持 | B11: 140円/$ ハードコード (I-O 17-21行) | C11: 意図的参考レート。C4で手動調整運用を尊重
A12: 保持 | B12: eBay手数料 18.5% (US) | C12: 実測18.37%と一致、TAX/miscバッファ込み構造
A13: 保持 | B13: 割引ラダー 5/8/10/15% | C13: オファー時・値下げ時の試算用
A14: 保持 | B14: US/UK/AU の3シート分離 | C14: 地域別に手数料率が異なるため
A15: 保持 | B15: 推奨行/オファー価格/試算行 | C15: 既存ワークフローを維持
A17: 作成日 | B17: 2026-04-12
A18: 作成者 | B18: Claude (iMakHQ 構想会話内で自動生成)
A19: 旧ファイル | B19: 【NEW】利益計算シート.xlsx (同じデスクトップ) | C19: 戻したい時はそちらを参照
A20: 追記 | B20: eBay公式FVF参考値セクションを設定シートに追加 | C20: TCG/Toys=13.25% / Clothing=15.30% +共通2%。主計算は未接続(参考のみ)
A21: 新規 | B21: カテゴリセレクタ追加 (各計算シート F1) | C21: I1 = VLOOKUP(F1, cat table) + 0.02 + 国別補正 で動的計算
A22: 修正 | B22: 設定!B17:B32 を公式FVF値に更新 (0.1325 or 0.1530) | C22: 旧: 手数料参考 (0.135等) → 新: eBay公式 FVF 2026
A23: 新規 | B23: 国別補正セル (K1) を各計算シートに追加 | C23: US:0% / UK:+5% / AU:-2% (VAT/GST関連の実測差を吸収)
